<mujoco>
  <compiler autolimits="true"/>

  <asset>
    <texture name="grid" type="2d" builtin="checker" width="512" height="512" rgb1=".1 .2 .3" rgb2=".2 .3 .4"/>
    <material name="grid" texture="grid" texrepeat="1 1" texuniform="true" reflectance=".2"/>
    
  </asset>

  <default>
    <joint damping=".03" actuatorfrcrange="-0.5 0.5"/>
    <default class="wheel">
      <geom type="cylinder" size=".03 .01" rgba=".5 .5 1 0.5"/>
    </default>
    <default class="decor">
      <site type="box" rgba=".5 1 .5 0.8"/>
    </default>
  </default>

  <worldbody>
    <!-- <camera name="front_cam" mode="fixed" pos="0.1 0 0.2" euler="0 -50 270" fovy="120"/>    -->

    <geom type="plane" size="30 30 .01" material="grid"/>
    <body name="car" pos="-1.9 1.3 .03" euler="0 0 270">
      <camera name="front_cam" mode="fixed" pos="0.1 0 0.2" euler="0 -50 270" fovy="120"/>   

      <site name="camera_site" pos="0.1 0 0.05" euler="0 15 0" size="0.001"/>

      <freejoint/>
      <light name="top light" pos="0 0 2" mode="trackcom" diffuse=".4 .4 .4"/>
      <geom name="chasis" mass="20" type="box" size="0.07 0.045 0.02" pos="0 0 0.05" rgba="0.9 0.1 1 1"/>
      <body name="left wheel" pos="-.07 .06 0" zaxis="0 1 0">
        <joint name="left"/>
        <geom class="wheel"/>
        <site class="decor" size=".006 .025 .0115"/>
        <site class="decor" size=".025 .006 .0115"/>
      </body>
      <body name="right wheel" pos="-.07 -.06 0" zaxis="0 1 0">
        <joint name="right"/>
        <geom class="wheel"/>
        <site class="decor" size=".006 .025 .0115"/>
        <site class="decor" size=".025 .006 .0115"/>
      </body>

      <body name="front left" pos=".07 .06 0" zaxis="0 1 0">
        <joint name="front left" damping="1" type="hinge" range="-30 30" axis="0 1 0"/>

        <joint name="j3"/>
        <geom class="wheel"/>
        <site class="decor" size=".006 .025 .0115"/>
        <site class="decor" size=".025 .006 .0115"/>
      </body>
      <body name="front right " pos=".07 -.06 0" zaxis="0 1 0">
        <joint name="front right" damping="1" type="hinge" range="-30 30" axis="0 1 0"/>
        <joint name="j4"/>
        <geom class="wheel"/>
        <site class="decor" size=".006 .025 .0115"/>
        <site class="decor" size=".025 .006 .0115"/>
      </body>



      <body name="fixed" pos="0.07 0 0" zaxis="1 0 0">
        <geom name="g4" type="box" size="0.001 0.045 0.001" rgba="0 0.5 0.5 1"/>
        <site name="s0" size="0.003" pos="0 0.045 0"/>
        <site name="s1" size="0.003" pos="0 -0.045 0"/>

     </body>

      <body pos="0.02 0 0">
        <joint name="acker" pos="0 0 0" type="slide" axis="0 1 0" />
        <geom type="box" size="0.001 0.035 0.001" rgba="1 0.3 0.3 1" />
        <site name="s5" size="0.003" pos="0 -0.035 0" rgba="1 0.5 0.5 1"/>
        <site name="s6" size="0.003" pos="0 0.035 0" rgba="1 0.5 0.5 1"/>


      </body>








    </body>
  </worldbody>

  <tendon>
    <!--fixed name="frontwheels">
      <joint joint="j4" coef=".5"/>

      <joint joint="j3" coef=".5"/>
    </fixed>
    <fixed name="backwheels">
      <joint joint="left" coef=".5"/>
      <joint joint="right" coef=".5"/>
    </fixed-->

    <fixed name="4x4">
      <joint joint="j4" coef=".5"/>
      <joint joint="j3" coef=".5"/>
      <joint joint="left" coef=".5"/>
      <joint joint="right" coef=".5"/>
    </fixed>


    <fixed name="turn_acker">
      <joint joint="front right" coef="1"/>
      <joint joint="front left" coef="1"/>
      <joint joint="acker" coef="-1" />

    </fixed>
    <fixed name="turn">
      <joint joint="front right" coef="10"/>
      <joint joint="front left" coef="10"/>

    </fixed>


    <!--fixed name="turn left wheel">
      <joint joint="front left" coef="0.5"/>
    </fixed>

    <fixed name="turn right wheel">
      <joint joint="front right" coef="0.5"/>
    </fixed-->

    <spatial  width=".001" stiffness="1000">
      <site site="s0"/>
      <site site="s6"/>
      <site site="s5"/>
      <site site="s1"/>
    </spatial>

  </tendon>

  <actuator>
    <!--motor name="run_front_wheels" tendon="frontwheels" ctrlrange="-100 100"/>
    <motor name="run_back_wheels" tendon="backwheels" ctrlrange="-100 100"/-->
    <motor name="4x4" tendon="4x4" ctrlrange="-100 100"/>

    <motor name="turn_acker" tendon="turn_acker" ctrlrange="-1 1"/>
    <motor name="turn" tendon="turn" ctrlrange="-1 1"/>

    <!--motor name="turn left wheel" tendon="turn left wheel" ctrlrange="-1 1"/>
    
    <motor name="turn right wheel" tendon="turn right wheel" ctrlrange="-1 1"/-->





  </actuator>

  <sensor>
    <jointactuatorfrc name="right" joint="right"/>
    <jointactuatorfrc name="left" joint="left"/>
  </sensor>
</mujoco>
