<mujoco>
  <compiler autolimits="true"/>

  <asset>
    <texture name="grid" type="2d" builtin="checker" width="512" height="512" rgb1=".1 .2 .3" rgb2=".2 .3 .4"/>
    <material name="grid" texture="grid" texrepeat="1 1" texuniform="true" reflectance=".2"/>
    
  </asset>

  <default>
    <joint damping=".03" actuatorfrcrange="-0.5 0.5"/>
    <default class="wheel">
      <geom type="cylinder" size=".03 .01" rgba=".5 .5 1 0.5"/>
    </default>
    <default class="decor">
      <site type="box" rgba=".5 1 .5 0.8"/>
    </default>
  </default>

  <worldbody>
    <geom type="plane" size="5 5 .01" material="grid"/>
    <body name="car" pos="-1.9 1.3 .03" euler="0 0 -90">
      <freejoint/>
      <light name="top light" pos="0 0 2" mode="trackcom" diffuse=".4 .4 .4"/>
      <geom name="chasis" type="box" size="0.07 0.045 0.02" rgba="0.9 0.1 1 0.9"/>
      <body name="left wheel" pos="-.07 .06 0" zaxis="0 1 0">
        <joint name="left"/>
        <geom class="wheel"/>
        <site class="decor" size=".006 .025 .0115"/>
        <site class="decor" size=".025 .006 .0115"/>
      </body>
      <body name="right_wheel" pos="-.07 -.06 0" zaxis="0 1 0">
        <joint name="right"/>
        <geom class="wheel"/>
        <site class="decor" size=".006 .025 .0115"/>
        <site class="decor" size=".025 .006 .0115"/>
      </body>
      <!-- <body name="front left wheel" pos=".07 .06 0" zaxis="0 1 0">
        <joint name="front_left" />
        <joint name="turn_front_left" axis="0 1 0" range="0 45" />

        <geom class="wheel"/>
        <site class="decor" size=".006 .025 .0115"/>
        <site class="decor" size=".025 .006 .0115"/>
      </body>
      <body name="front right wheel" pos=".07 -.06 0" zaxis="0 1 0">
        <joint name="turn_front_right" axis="0 0 1" range="0 45" />
        <body pos="0 0 0" zaxis="0 1 0">
          <joint name="front_right" type="hinge" axis="0 1 0"//>
          <geom class="wheel"/>
          <site class="decor" size=".006 .025 .0115"/>
          <site class="decor" size=".025 .006 .0115"/>
        </body>  
      </body> -->
            <!-- FRONT LEFT WHEEL with steering -->
      <body name="front_left_caster" pos=".07 .06 0">
       <!-- Ð”Ð¾Ð±Ð°Ð²Ð»ÑÐµÐ¼ Ð¼Ð°Ð»ÐµÐ½ÑŒÐºÐ¸Ð¹ Ð½ÐµÐ²Ð¸Ð´Ð¸Ð¼Ñ‹Ð¹ geom Ð´Ð»Ñ Ð¼Ð°ÑÑÑ‹ -->
        <geom type="sphere" size="0.001" mass="0.001" rgba="0 0 0 0"/>    
        <!-- ÐŸÐ¾Ð²Ð¾Ñ€Ð¾Ñ‚ Ð²Ð»ÐµÐ²Ð¾/Ð²Ð¿Ñ€Ð°Ð²Ð¾ (Ñ€ÑƒÐ»ÐµÐ²Ð¾Ðµ ÑƒÐ¿Ñ€Ð°Ð²Ð»ÐµÐ½Ð¸Ðµ) -->
        <joint name="turn_front_left" type="hinge" axis="0 0 1"/>
        
        <body name="front_left_wheel" pos="0 0 0" zaxis="0 1 0">
          <!-- Ð’Ñ€Ð°Ñ‰ÐµÐ½Ð¸Ðµ ÐºÐ¾Ð»ÐµÑÐ° -->
          <joint name="front_left" type="hinge" axis="0 1 0"/>
          <geom class="wheel"/>
          <site class="decor" size=".006 .025 .0115"/>
          <site class="decor" size=".025 .006 .0115"/>
        </body>
      </body>

      <!-- FRONT RIGHT WHEEL with steering -->
      <body name="front_right_caster" pos=".07 -.06 0">
        <geom type="sphere" size="0.001" mass="0.001" rgba="0 0 0 0"/>    

        <!-- ÐŸÐ¾Ð²Ð¾Ñ€Ð¾Ñ‚ Ð²Ð¿Ñ€Ð°Ð²Ð¾/Ð²Ð»ÐµÐ²Ð¾ -->
        <joint name="turn_front_right" type="hinge" axis="0 0 1"/>
        
        <body name="front_right_wheel" pos="0 0 0" zaxis="0 1 0">
          <!-- Ð’Ñ€Ð°Ñ‰ÐµÐ½Ð¸Ðµ ÐºÐ¾Ð»ÐµÑÐ° -->
          <joint name="front_right" type="hinge" axis="0 1 0"/>
          <geom class="wheel"/>
          <site class="decor" size=".006 .025 .0115"/>
          <site class="decor" size=".025 .006 .0115"/>
        </body>
      </body>




      <body name="fixed" pos="0.07 0 0" zaxis="1 0 0">
        <geom name="g4" type="box" size="0.001 0.045 0.001" rgba="0 0.5 0.5 1"/>
        <site name="s0" size="0.003" pos="0 0.045 0"/>
        <site name="s1" size="0.003" pos="0 -0.045 0"/>

     </body>
<!-- 
      <body name="os_ackerm" pos="0.04 0 0">
        <joint name="acker" type="slide" axis="0 1 0" />
        <geom type="box" size="0.001 0.035 0.001" rgba="1 0.3 0.3 1" />
        <site name="s5" size="0.003" pos="0 -0.035 0" rgba="1 0.5 0.5 1"/>
        <site name="s6" size="0.003" pos="0 0.035 0" rgba="1 0.5 0.5 1"/>
      </body> -->


    <!-- ÐÐ¾Ð²Ñ‹Ð¹ site Ð´Ð»Ñ IMU -->
    <site name="imu" pos="0 0 0.02" size="0.005" rgba="1 1 0 1"/>
    <!-- Ð¡ÐµÐ½ÑÐ¾Ñ€Ñ‹ Ñ€Ð°ÑÑÑ‚Ð¾ÑÐ½Ð¸Ñ / ÐºÐ°ÑÐ°Ð½Ð¸Ñ -->
    <site name="sensor_front" pos="0.09 0 0.02" size="0.005" rgba="1 0 0 1"/>
    <site name="sensor_left"  pos="0 0.07 0.02" size="0.005" rgba="0 1 0 1"/>
    <site name="sensor_right" pos="0 -0.07 0.02" size="0.005" rgba="0 0 1 1"/>






    </body>
  </worldbody>

  <tendon>
    <fixed name="forward">
      <joint joint="front_left" coef=".5"/>
      <joint joint="front_right" coef=".5"/>
    </fixed>
    <fixed name="turn">
      <joint joint="turn_front_left" coef="-1"/>
      <joint joint="turn_front_right" coef="1"/>
    </fixed>

    <fixed name="turn left wheel">
      <joint joint="front_left" coef="-0.5"/>
    </fixed>

    <fixed name="turn right wheel">
      <joint joint="front_right" coef="-0.5"/>
    </fixed>

    <!-- <spatial  width=".001" stiffness="0.1">
      <site site="s0"/>
      <site site="s6"/>
      <site site="s5"/>
      <site site="s1"/>
    </spatial> -->

  </tendon>

  <actuator>
    <motor name="forward" tendon="forward" ctrlrange="-100 100"/>
    <motor name="turn" tendon="turn" ctrlrange="-180 180"/>
    <!-- ðŸ”§ ÐÐ¾Ð²Ñ‹Ðµ Ð¼Ð¾Ñ‚Ð¾Ñ€Ñ‹ Ð´Ð»Ñ Ð¿Ð¾Ð²Ð¾Ñ€Ð¾Ñ‚Ð° Ð¿ÐµÑ€ÐµÐ´Ð½Ð¸Ñ… ÐºÐ¾Ð»ÐµÑ -->    
    <motor name="steer_left" joint="turn_front_left" ctrlrange="-0.5 0.5"/>
    <motor name="steer_right" joint="turn_front_right" ctrlrange="-0.5 0.5"/>
    
    <!-- <motor name="turn left wheel" tendon="turn left wheel" ctrlrange="-1 1"/>
    <motor name="turn right wheel" tendon="turn right wheel" ctrlrange="-1 1"/> -->
  </actuator>





   <sensor>
    <!-- Ð”Ð°Ñ‚Ñ‡Ð¸ÐºÐ¸ Ð½Ð°Ð³Ñ€ÑƒÐ·ÐºÐ¸ Ð½Ð° Ð´Ð²Ð¸Ð³Ð°Ñ‚ÐµÐ»Ð¸ -->
    <jointactuatorfrc name="right" joint="right"/>
    <jointactuatorfrc name="left" joint="left"/>

    <!-- Ð“Ð¸Ñ€Ð¾ÑÐºÐ¾Ð¿ -->
    <gyro name="gyro" site="imu"/>

    <!-- ÐÐºÑÐµÐ»ÐµÑ€Ð¾Ð¼ÐµÑ‚Ñ€ -->
    <accelerometer name="accel" site="imu"/>

    <!-- Ð›Ð°Ð·ÐµÑ€Ð½Ñ‹Ðµ Ð´Ð°Ð»ÑŒÐ½Ð¾Ð¼ÐµÑ€Ñ‹ -->
    <rangefinder name="range_front" site="sensor_front"/>
    <rangefinder name="range_left" site="sensor_left"/>
    <rangefinder name="range_right" site="sensor_right"/>

    <!-- Ð¡ÐµÐ½ÑÐ¾Ñ€Ñ‹ ÐºÐ¾Ð½Ñ‚Ð°ÐºÑ‚Ð° (Ñ‚Ð°Ñ‡-ÑÐµÐ½ÑÐ¾Ñ€Ñ‹) -->
    <touch name="touch_front" site="sensor_front"/>
    <touch name="touch_left" site="sensor_left"/>
    <touch name="touch_right" site="sensor_right"/>
  </sensor>


</mujoco>
